<?xml version="1.0"?>
<robot name="swarm_robot">
  <!-- Robot Properties -->
  <material name="blue">
    <color rgba="0.0 0.0 0.8 1.0"/>
  </material>
  <material name="black">
    <color rgba="0.0 0.0 0.0 1.0"/>
  </material>
  <material name="white">
    <color rgba="1.0 1.0 1.0 1.0"/>
  </material>
  
  <!-- Base Link (Main body) -->
  <link name="base_link">
    <inertial>
      <mass value="0.5"/>
      <origin xyz="0 0 0.025" rpy="0 0 0"/>
      <inertia ixx="0.001" ixy="0" ixz="0" iyy="0.001" iyz="0" izz="0.001"/>
    </inertial>
    <visual>
      <origin xyz="0 0 0.025" rpy="0 0 0"/>
      <geometry>
        <cylinder radius="0.05" length="0.05"/>
      </geometry>
      <material name="blue"/>
    </visual>
    <collision>
      <origin xyz="0 0 0.025" rpy="0 0 0"/>
      <geometry>
        <cylinder radius="0.05" length="0.05"/>
      </geometry>
    </collision>
  </link>
  
  <!-- Left Wheel -->
  <link name="left_wheel">
    <inertial>
      <mass value="0.1"/>
      <origin xyz="0 0 0" rpy="0 0 0"/>
      <inertia ixx="0.0001" ixy="0" ixz="0" iyy="0.0001" iyz="0" izz="0.0001"/>
    </inertial>
    <visual>
      <origin xyz="0 0 0" rpy="1.5707 0 0"/>
      <geometry>
        <cylinder radius="0.02" length="0.01"/>
      </geometry>
      <material name="black"/>
    </visual>
    <collision>
      <origin xyz="0 0 0" rpy="1.5707 0 0"/>
      <geometry>
        <cylinder radius="0.02" length="0.01"/>
      </geometry>
    </collision>
  </link>
  
  <!-- Right Wheel -->
  <link name="right_wheel">
    <inertial>
      <mass value="0.1"/>
      <origin xyz="0 0 0" rpy="0 0 0"/>
      <inertia ixx="0.0001" ixy="0" ixz="0" iyy="0.0001" iyz="0" izz="0.0001"/>
    </inertial>
    <visual>
      <origin xyz="0 0 0" rpy="1.5707 0 0"/>
      <geometry>
        <cylinder radius="0.02" length="0.01"/>
      </geometry>
      <material name="black"/>
    </visual>
    <collision>
      <origin xyz="0 0 0" rpy="1.5707 0 0"/>
      <geometry>
        <cylinder radius="0.02" length="0.01"/>
      </geometry>
    </collision>
  </link>

 


  
  <!-- Caster Wheel -->
  <link name="caster_wheel">
    <inertial>
      <mass value="0.05"/>
      <origin xyz="0 0 0" rpy="0 0 0"/>
      <inertia ixx="0.00001" ixy="0" ixz="0" iyy="0.00001" iyz="0" izz="0.00001"/>
    </inertial>
    <visual>
      <origin xyz="0 0 0" rpy="0 0 0"/>
      <geometry>
        <sphere radius="0.01"/>
      </geometry>
      <material name="black"/>
    </visual>
    <collision>
      <origin xyz="0 0 0" rpy="0 0 0"/>
      <geometry>
        <sphere radius="0.01"/>
      </geometry>
    </collision>
  </link>
  
  <!-- Sensor Tower -->
  <link name="sensor_tower">
    <inertial>
      <mass value="0.1"/>
      <origin xyz="0 0 0.025" rpy="0 0 0"/>
      <inertia ixx="0.0001" ixy="0" ixz="0" iyy="0.0001" iyz="0" izz="0.00001"/>
    </inertial>
    <visual>
      <origin xyz="0 0 0.025" rpy="0 0 0"/>
      <geometry>
        <cylinder radius="0.01" length="0.05"/>
      </geometry>
      <material name="white"/>
    </visual>
    <collision>
      <origin xyz="0 0 0.025" rpy="0 0 0"/>
      <geometry>
        <cylinder radius="0.01" length="0.05"/>
      </geometry>
    </collision>
  </link>
  
  <!-- IR Sensor -->
  <link name="ir_sensor">
    <inertial>
      <mass value="0.01"/>
      <origin xyz="0 0 0" rpy="0 0 0"/>
      <inertia ixx="0.000001" ixy="0" ixz="0" iyy="0.000001" iyz="0" izz="0.000001"/>
    </inertial>
    <visual>
      <origin xyz="0 0 0" rpy="0 0 0"/>
      <geometry>
        <box size="0.01 0.01 0.01"/>
      </geometry>
      <material name="black"/>
    </visual>
    <collision>
      <origin xyz="0 0 0" rpy="0 0 0"/>
      <geometry>
        <box size="0.01 0.01 0.01"/>
      </geometry>
    </collision>
  </link>
  
  <!-- Communication Antenna -->
  <link name="antenna">
    <inertial>
      <mass value="0.01"/>
      <origin xyz="0 0 0.02" rpy="0 0 0"/>
      <inertia ixx="0.000001" ixy="0" ixz="0" iyy="0.000001" iyz="0" izz="0.0000001"/>
    </inertial>
    <visual>
      <origin xyz="0 0 0.02" rpy="0 0 0"/>
      <geometry>
        <cylinder radius="0.001" length="0.04"/>
      </geometry>
      <material name="black"/>
    </visual>
  </link>
  
  <!-- Joint Definitions -->
  <!-- Left Wheel Joint -->
  <joint name="left_joint" type="continuous">
    <parent link="base_link"/>
    <child link="left_wheel"/>
    <origin xyz="0 0.06 0.02" rpy="0 0 0"/>
    <axis xyz="0 1 0"/>
    <dynamics damping="0.1"/>
  </joint>
  
  <!-- Right Wheel Joint -->
  <joint name="right_joint" type="continuous">
    <parent link="base_link"/>
    <child link="right_wheel"/>
    <origin xyz="0 -0.06 0.02" rpy="0 0 0"/>
    <axis xyz="0 -1 0"/>
    <dynamics damping="0.1"/>
  </joint>
  
  <!-- Caster Wheel Joint -->
  <joint name="caster_wheel_joint" type="fixed">
    <parent link="base_link"/>
    <child link="caster_wheel"/>
    <origin xyz="0.035 0 0.01" rpy="0 0 0"/>
  </joint>
  
  <!-- Sensor Tower Joint -->
  <joint name="sensor_tower_joint" type="fixed">
    <parent link="base_link"/>
    <child link="sensor_tower"/>
    <origin xyz="0 0 0.05" rpy="0 0 0"/>
  </joint>
  
  <!-- IR Sensor Joint -->
  <joint name="ir_sensor_joint" type="fixed">
    <parent link="sensor_tower"/>
    <child link="ir_sensor"/>
    <origin xyz="0.01 0 0.05" rpy="0 0 0"/>
  </joint>
  
  <!-- Antenna Joint -->
  <joint name="antenna_joint" type="fixed">
    <parent link="sensor_tower"/>
    <child link="antenna"/>
    <origin xyz="0 0 0.05" rpy="0 0 0"/>
  </joint>
  
  <!-- Transmissions for Control -->
  <transmission name="left_wheel_trans">
    <type>transmission_interface/SimpleTransmission</type>
    <joint name="left_joint">
      <hardwareInterface>hardware_interface/VelocityJointInterface</hardwareInterface>
    </joint>
    <actuator name="left_wheel_motor">
      <hardwareInterface>hardware_interface/VelocityJointInterface</hardwareInterface>
      <mechanicalReduction>1</mechanicalReduction>
    </actuator>
  </transmission>
  
  <transmission name="right_wheel_trans">
    <type>transmission_interface/SimpleTransmission</type>
    <joint name="right_joint">
      <hardwareInterface>hardware_interface/VelocityJointInterface</hardwareInterface>
    </joint>
    <actuator name="right_wheel_motor">
      <hardwareInterface>hardware_interface/VelocityJointInterface</hardwareInterface>
      <mechanicalReduction>1</mechanicalReduction>
    </actuator>
  </transmission>
  
  <!-- Gazebo Plugin for Differential Drive -->
  <gazebo>
    <plugin name="differential_drive_controller" filename="libgazebo_ros_diff_drive.so">
      <legacyMode>false</legacyMode>
      <alwaysOn>true</alwaysOn>
      <updateRate>20</updateRate>
      <leftJoint>left_joint</leftJoint>
      <rightJoint>right_joint</rightJoint>
      <wheelSeparation>0.12</wheelSeparation>
      <wheelDiameter>0.04</wheelDiameter>
      <torque>0.1</torque>
      <commandTopic>cmd_vel</commandTopic>
      <odometryTopic>odom</odometryTopic>
      <odometryFrame>odom</odometryFrame>
      <robotBaseFrame>base_link</robotBaseFrame>
      <publishWheelTF>false</publishWheelTF>
      <publishOdomTF>true</publishOdomTF>
      <publishWheelJointState>true</publishWheelJointState>
      <wheelAcceleration>0.5</wheelAcceleration>
      <wheelTorque>0.1</wheelTorque>
      <rosDebugLevel>na</rosDebugLevel>
    </plugin>
  </gazebo>
  
  <!-- IR Sensor Gazebo Configuration -->
  <gazebo reference="ir_sensor">
    <sensor type="ray" name="ir_sensor">
      <pose>0 0 0 0 0 0</pose>
      <visualize>true</visualize>
      <update_rate>10</update_rate>
      <ray>
        <scan>
          <horizontal>
            <samples>5</samples>
            <resolution>1</resolution>
            <min_angle>-0.2</min_angle>
            <max_angle>0.2</max_angle>
          </horizontal>
        </scan>
        <range>
          <min>0.01</min>
          <max>0.3</max>
          <resolution>0.01</resolution>
        </range>
      </ray>
      <plugin name="gazebo_ros_ir_sensor_controller" filename="libgazebo_ros_range.so">
        <gaussianNoise>0.005</gaussianNoise>
        <alwaysOn>true</alwaysOn>
        <updateRate>10</updateRate>
        <topicName>ir_sensor</topicName>
        <frameName>ir_sensor</frameName>
        <radiation>infrared</radiation>
        <fov>0.4</fov>
      </plugin>
    </sensor>
  </gazebo>
</robot>